Workbook
Name Closing_Probability: List!$F$3:$F$10
Name If_OutsideBroker: List!$B$3:$B$4

Sheet Template
F1: ="# of Projects: " & SUBTOTAL(3,D7:D1048576) -> # of Projects: 37 | AU1: =SUBTOTAL(9,AU7:AU1048576) -> 2800000 | AV1: =SUBTOTAL(9,AV7:AV1048576) -> 2780500 | BE1: =SUBTOTAL(9,BE7:BE1048576) -> 2780500 | BF1: =SUBTOTAL(9,BF7:BF1048576) -> 1390250 | BG1: =SUBTOTAL(9,BG7:BG1048576) -> 1390250 | BH1: =SUBTOTAL(9,BH7:BH1048576) -> 656150 | BI1: =SUBTOTAL(9,BI7:BI1048576) -> 356000 | BJ1: =SUBTOTAL(9,BJ7:BJ1048576) -> 378100 | BL1: =SUBTOTAL(9,BL7:BL1048576) -> 570375 | BM1: =SUBTOTAL(9,BM7:BM1048576) -> 285187.5 | BN1: =SUBTOTAL(9,BN7:BN1048576) -> 285187.5 | BO1: =SUBTOTAL(9,BO7:BO1048576) -> 111112.5 | BP1: =SUBTOTAL(9,BP7:BP1048576) -> 120000 | BQ1: =SUBTOTAL(9,BQ7:BQ1048576) -> 54075
AS3: Input | AT3: Input | AU3: Input | AV3: Input | AW3: Drop Down | AX3: Drop Down | AY3: Input
D4: Copy & Paste | AL4: Finance Input | AS4: Required: Review & Update | BA4: Formula | BB4: Formula | BC4: Formula | BE4: Formula | BF4: Formula | BG4: Formula | BH4: Formula | BI4: Formula | BJ4: Formula | BL4: Formula w/ Prob | BM4: Formula w/ Prob | BN4: Formula w/ Prob | BO4: Formula w/ Prob | BP4: Formula w/ Prob | BQ4: Formula w/ Prob
C6: Index | D6: Project Name | E6: Lead Broker | F6: Project Coordinator | G6: Site Code | H6: Launch Year | I6: Record Type | J6: Stage | K6: Status | L6: Requestor Org | M6: Facility Type | N6: Transaction Type | O6: Building Type | P6: Property Name | Q6: Property Market | R6: Address | S6: City | T6: State | U6: Postal/Zip Code | V6: Property Country | W6: Location (Latitude) | X6: Location (Longitude) | Y6: Leased SF | Z6: Land Size (Acres) | AA6: Market Surveyed | AB6: Site Selected | AC6: LOI Concluded | AD6: CAR Approved | AE6: Mutual Acceptance/PSA Execution | AF6: Lease Execution Forecast (Shield) | AG6: Date of Close Forecast (Shield) | AH6: Requirement: Off POR | AI6: KBC Case Safe ID | AJ6: Client Case Safe ID | AK6: x | AL6: NEW vs. EXISTING | AM6: Direction | AN6: 1st Payment Date | AO6: 1st Payment Date % | AP6: 2nd Payment Date | AQ6: 2nd Payment Date % | AR6: xxxx | AS6: Updated: Execution Date | AT6: Updated: Launch Forecast | AU6: Est. Consulting Fee | AV6: Est. Total Commission | AW6: Closing Probability | AX6: Is there an Outside Broker | AY6: Broker Notes | AZ6: xxx | BA6: KBC Advisors LLC Split | BB6: KBC Local Market Split | BC6: Outside Broker Split | BD6: xxxxx | BE6: Est. Total Commission | BF6: Est. Amazon Rebate | BG6: Est. Commission | BH6: Commission - KBC Advisors LLC | BI6: Commission - KBC Local Market | BJ6: Commission - Outside Broker | BK6: xxxxxx | BL6: Est. Total Commission | BM6: Est. Amazon Rebate | BN6: Est. Commission | BO6: Commission - KBC Advisors LLC | BP6: Commission - KBC Local Market | BQ6: Commission - Outside Broker
C7: 39 | D7: CVG47-Purchase | E7: Jason Kirkham | F7: Nicole Rasmussen | G7: CVG47 | H7: 2026 | I7: Project | J7: PSA Execution | K7: Active | L7: ATS | M7: CNG Fill Station | N7: Purchase | O7: Build to Suit | P7: Litton Lane Hebron KY | Q7: Cincinnati | R7: Litton Lane | S7: Hebron | T7: KY | U7: 41048 | V7: United States | W7: 39.073614 | X7: -84.714308 | Z7: 66.5 | AA7: 45645 | AB7: 45618 | AC7: 45703 | AE7: 45735 | AG7: 46059 | AI7: a0ERc00000E5gl2MAB | AJ7: a003t00001JRvImAAL | AL7: Existing | AR7: x | AS7: 45747 | AT7: 46325 | AU7: 400000 | AV7: 400000 | AW7: 0 | AX7: YES | AZ7: x | BA7: =IFERROR(VLOOKUP($AX7,List!B:C,2,FALSE),"N/A") -> 0.6 | BB7: =IF(AX7="YES",0, IF(AX7="NO",(1-BA7),"N/A")) -> 0 | BC7: =IF(AX7="YES",(1-BA7),IF(AX7="NO",0,"N/A")) -> 0.4 | BE7: =IFERROR(AV7,0) -> 400000 | BF7: =IFERROR(MAX(BE7-MIN(600000,BE7/2),0),0) -> 200000 | BG7: =IFERROR(MIN(600000,BE7/2),0) -> 200000 | BH7: =IFERROR(BG7*BA7,0) -> 120000 | BI7: =IFERROR(BG7*BB7,0) -> 0 | BJ7: =IFERROR(BG7*BC7,0) -> 80000 | BL7: =$AW7*BE7 -> 0 | BM7: =$AW7*BF7 -> 0 | BN7: =$AW7*BG7 -> 0 | BO7: =$AW7*BH7 -> 0 | BP7: =$AW7*BI7 -> 0 | BQ7: =$AW7*BJ7 -> 0
C8: 50 | D8: DII9-Purchase | E8: Jason Kirkham | F8: Kinsley West | G8: DII9 | H8: 2027 | I8: Project | J8: Escrow/Due Diligence | K8: Active | L8: R2L | M8: RSR - DS | N8: Purchase | O8: Build to Suit | P8: 408 Alexander Avenue Fraziers Bottom WV | Q8: Charleston (WV) | R8: 408 Alexander Avenue | S8: Fraziers Bottom | T8: WV | U8: 25213 | V8: United States | W8: 38.561393 | X8: -81.979204 | Z8: 37 | AB8: 45132 | AC8: 45033 | AD8: 45905 | AG8: 46167 | AI8: a0ERc000000CHczMAG | AJ8: a003t00001AgiT4AAJ | AL8: Existing | AR8: x | AS8: 45976 | AT8: 46280 | AU8: 400000 | AV8: 40500 | AW8: 0.75 | AX8: YES | AZ8: x | BA8: =IFERROR(VLOOKUP($AX8,List!B:C,2,FALSE),"N/A") -> 0.6 | BB8: =IF(AX8="YES",0, IF(AX8="NO",(1-BA8),"N/A")) -> 0 | BC8: =IF(AX8="YES",(1-BA8),IF(AX8="NO",0,"N/A")) -> 0.4 | BE8: =IFERROR(AV8,0) -> 40500 | BF8: =IFERROR(MAX(BE8-MIN(600000,BE8/2),0),0) -> 20250 | BG8: =IFERROR(MIN(600000,BE8/2),0) -> 20250 | BH8: =IFERROR(BG8*BA8,0) -> 12150 | BI8: =IFERROR(BG8*BB8,0) -> 0 | BJ8: =IFERROR(BG8*BC8,0) -> 8100 | BL8: =$AW8*BE8 -> 30375 | BM8: =$AW8*BF8 -> 15187.5 | BN8: =$AW8*BG8 -> 15187.5 | BO8: =$AW8*BH8 -> 9112.5 | BP8: =$AW8*BI8 -> 0 | BQ8: =$AW8*BJ8 -> 6075
C9: 57 | D9: ZIN3-New Lease | E9: Jason Kirkham | F9: Jacob Sleight | G9: ZIN3_QC | H9: 2026 | I9: Project | J9: LOI Concluded | K9: Active | L9: R2L | M9: Quick Commerce | N9: New Lease | O9: Existing | P9: Carmel Tech Center Building 2 12208 Hancock Street Carmel IN | R9: 12208 Hancock Street | S9: Carmel | T9: IN | U9: 46032 | V9: United States | W9: 39.96574 | X9: -86.15223 | Y9: 7062 | Z9: 5.63 | AA9: 46009 | AB9: 46052 | AC9: 46066 | AF9: 46175 | AI9: a0ERc00000SNBSZMA5 | AJ9: a00at00000LdA1qAAF | AL9: New | AR9: x | AZ9: x | BA9: =IFERROR(VLOOKUP($AX9,List!B:C,2,FALSE),"N/A") -> N/A | BB9: =IF(AX9="YES",0, IF(AX9="NO",(1-BA9),"N/A")) -> N/A | BC9: =IF(AX9="YES",(1-BA9),IF(AX9="NO",0,"N/A")) -> N/A | BE9: =IFERROR(AV9,0) -> 0 | BF9: =IFERROR(MAX(BE9-MIN(600000,BE9/2),0),0) -> 0 | BG9: =IFERROR(MIN(600000,BE9/2),0) -> 0 | BH9: =IFERROR(BG9*BA9,0) -> 0 | BI9: =IFERROR(BG9*BB9,0) -> 0 | BJ9: =IFERROR(BG9*BC9,0) -> 0 | BL9: =$AW9*BE9 -> 0 | BM9: =$AW9*BF9 -> 0 | BN9: =$AW9*BG9 -> 0 | BO9: =$AW9*BH9 -> 0 | BP9: =$AW9*BI9 -> 0 | BQ9: =$AW9*BJ9 -> 0
C10: 62 | D10: ZIN1-New Lease | E10: Jason Kirkham | F10: Jacob Sleight | G10: ZIN1_QC | H10: 2026 | I10: Project | J10: LOI Concluded | K10: Active | L10: R2L | M10: Quick Commerce | N10: New Lease | O10: Existing | P10: Milky Way Complex 4191 Millersville Road Indianapolis IN | R10: 4191 Millersville Road | S10: Indianapolis | T10: IN | U10: 46205 | V10: United States | W10: 39.83307 | X10: -86.11404 | Y10: 4100 | Z10: 3.5 | AA10: 46009 | AB10: 46049 | AC10: 46036 | AF10: 46178 | AI10: a0ERc00000S8ae5MAB | AJ10: a00at00000LdABWAA3 | AL10: New | AR10: x | AZ10: x | BA10: =IFERROR(VLOOKUP($AX10,List!B:C,2,FALSE),"N/A") -> N/A | BB10: =IF(AX10="YES",0, IF(AX10="NO",(1-BA10),"N/A")) -> N/A | BC10: =IF(AX10="YES",(1-BA10),IF(AX10="NO",0,"N/A")) -> N/A | BE10: =IFERROR(AV10,0) -> 0 | BF10: =IFERROR(MAX(BE10-MIN(600000,BE10/2),0),0) -> 0 | BG10: =IFERROR(MIN(600000,BE10/2),0) -> 0 | BH10: =IFERROR(BG10*BA10,0) -> 0 | BI10: =IFERROR(BG10*BB10,0) -> 0 | BJ10: =IFERROR(BG10*BC10,0) -> 0 | BL10: =$AW10*BE10 -> 0 | BM10: =$AW10*BF10 -> 0 | BN10: =$AW10*BG10 -> 0 | BO10: =$AW10*BH10 -> 0 | BP10: =$AW10*BI10 -> 0 | BQ10: =$AW10*BJ10 -> 0
C11: 93 | D11: ZCL2-New Lease | E11: Jason Kirkham | F11: Jacob Sleight | G11: ZCL2 | H11: 2026 | I11: Project | J11: LOI Concluded | K11: Active | L11: R2L | M11: Quick Commerce | N11: New Lease | O11: Existing | P11: 4335-4365 Cranwood Parkway Cleveland OH | R11: 4335-4365 Cranwood Parkway | S11: Cleveland | T11: OH | U11: 44128 | V11: United States | W11: 41.44104 | X11: -81.54876 | Y11: 7770 | Z11: 2.56 | AB11: 46084 | AC11: 46107 | AF11: 46192 | AI11: a0ERc00000TInJMMA1 | AJ11: a00at00000PZqQPAA1 | AL11: New | AR11: x | AZ11: x | BA11: =IFERROR(VLOOKUP($AX11,List!B:C,2,FALSE),"N/A") -> N/A | BB11: =IF(AX11="YES",0, IF(AX11="NO",(1-BA11),"N/A")) -> N/A | BC11: =IF(AX11="YES",(1-BA11),IF(AX11="NO",0,"N/A")) -> N/A | BE11: =IFERROR(AV11,0) -> 0 | BF11: =IFERROR(MAX(BE11-MIN(600000,BE11/2),0),0) -> 0 | BG11: =IFERROR(MIN(600000,BE11/2),0) -> 0 | BH11: =IFERROR(BG11*BA11,0) -> 0 | BI11: =IFERROR(BG11*BB11,0) -> 0 | BJ11: =IFERROR(BG11*BC11,0) -> 0 | BL11: =$AW11*BE11 -> 0 | BM11: =$AW11*BF11 -> 0 | BN11: =$AW11*BG11 -> 0 | BO11: =$AW11*BH11 -> 0 | BP11: =$AW11*BI11 -> 0 | BQ11: =$AW11*BJ11 -> 0
C12: 94 | D12: ZDT6-New Lease | E12: Jason Kirkham | F12: Jacob Sleight | G12: ZDT6_QC | H12: 2026 | I12: Project | J12: LOI Concluded | K12: Active | L12: R2L | M12: Quick Commerce | N12: New Lease | O12: Existing | P12: Building C 313 East Hudson Avenue Royal Oak MI | Q12: Detroit | R12: 313 East Hudson Avenue | S12: Royal Oak | T12: MI | U12: 48067 | V12: United States | W12: 42.481867 | X12: -83.140051 | Y12: 12513 | Z12: 2.49 | AA12: 46058 | AB12: 46098 | AC12: 46122 | AF12: 46192 | AI12: a0ERc00000TkqpPMAR | AJ12: a00at00000PzVobAAF | AL12: New | AR12: x | AZ12: x | BA12: =IFERROR(VLOOKUP($AX12,List!B:C,2,FALSE),"N/A") -> N/A | BB12: =IF(AX12="YES",0, IF(AX12="NO",(1-BA12),"N/A")) -> N/A | BC12: =IF(AX12="YES",(1-BA12),IF(AX12="NO",0,"N/A")) -> N/A | BE12: =IFERROR(AV12,0) -> 0 | BF12: =IFERROR(MAX(BE12-MIN(600000,BE12/2),0),0) -> 0 | BG12: =IFERROR(MIN(600000,BE12/2),0) -> 0 | BH12: =IFERROR(BG12*BA12,0) -> 0 | BI12: =IFERROR(BG12*BB12,0) -> 0 | BJ12: =IFERROR(BG12*BC12,0) -> 0 | BL12: =$AW12*BE12 -> 0 | BM12: =$AW12*BF12 -> 0 | BN12: =$AW12*BG12 -> 0 | BO12: =$AW12*BH12 -> 0 | BP12: =$AW12*BI12 -> 0 | BQ12: =$AW12*BJ12 -> 0
C13: 96 | D13: DKE3-1-Purchase | E13: Jason Kirkham | F13: Mackenzie Floyd | G13: DKE3-1 | H13: 2027 | I13: Project | J13: PSA Execution | K13: Active | L13: AMZL | M13: Delivery Station | N13: Purchase | O13: Build to Suit | P13: Hickory Lane and Linde Lane Deforest WI | Q13: Milwaukee/Madison | R13: Hickory Lane and Linde Lane | S13: DeForest | T13: WI | U13: 53532 | V13: United States | W13: 43.245719 | X13: -89.384566 | Y13: 223285 | Z13: 48.09 | AA13: 45791 | AB13: 45866 | AC13: 45897 | AE13: 45960 | AG13: 46195 | AI13: a0ERc00000LN6tRMAT | AJ13: a00at00000DWZ3GAAX | AL13: Existing | AR13: x | AS13: 46053 | AT13: 46388 | AU13: 400000 | AV13: 500000 | AW13: 0.25 | AX13: YES | AZ13: x | BA13: =IFERROR(VLOOKUP($AX13,List!B:C,2,FALSE),"N/A") -> 0.6 | BB13: =IF(AX13="YES",0, IF(AX13="NO",(1-BA13),"N/A")) -> 0 | BC13: =IF(AX13="YES",(1-BA13),IF(AX13="NO",0,"N/A")) -> 0.4 | BE13: =IFERROR(AV13,0) -> 500000 | BF13: =IFERROR(MAX(BE13-MIN(600000,BE13/2),0),0) -> 250000 | BG13: =IFERROR(MIN(600000,BE13/2),0) -> 250000 | BH13: =IFERROR(BG13*BA13,0) -> 150000 | BI13: =IFERROR(BG13*BB13,0) -> 0 | BJ13: =IFERROR(BG13*BC13,0) -> 100000 | BL13: =$AW13*BE13 -> 125000 | BM13: =$AW13*BF13 -> 62500 | BN13: =$AW13*BG13 -> 62500 | BO13: =$AW13*BH13 -> 37500 | BP13: =$AW13*BI13 -> 0 | BQ13: =$AW13*BJ13 -> 25000
C14: 97 | D14: DSB2-Purchase | E14: Jason Kirkham | F14: Mackenzie Floyd | G14: DSB2 | H14: 2027 | I14: Project | J14: PSA Execution | K14: Active | L14: AMZL | M14: Delivery Station | N14: Purchase | O14: Build to Suit | P14: South Pointe Enterprise Campus Sheboygan WI | Q14: Green Bay | R14: South Pointe Enterprise Campus | S14: Sheboygan | T14: WI | U14: 53081 | V14: United States | W14: 43.689053 | X14: -87.753611 | Y14: 223285 | Z14: 107 | AB14: 45853 | AC14: 45880 | AD14: 45966 | AE14: 46048 | AG14: 46196 | AI14: a0ERc00000KsvtpMAB | AJ14: a003t00001JXDP6AAP | AL14: Existing | AR14: x | AS14: 45901 | AT14: 46143 | AU14: 400000 | AV14: 490000 | AW14: 0 | AX14: YES | AZ14: x | BA14: =IFERROR(VLOOKUP($AX14,List!B:C,2,FALSE),"N/A") -> 0.6 | BB14: =IF(AX14="YES",0, IF(AX14="NO",(1-BA14),"N/A")) -> 0 | BC14: =IF(AX14="YES",(1-BA14),IF(AX14="NO",0,"N/A")) -> 0.4 | BE14: =IFERROR(AV14,0) -> 490000 | BF14: =IFERROR(MAX(BE14-MIN(600000,BE14/2),0),0) -> 245000 | BG14: =IFERROR(MIN(600000,BE14/2),0) -> 245000 | BH14: =IFERROR(BG14*BA14,0) -> 147000 | BI14: =IFERROR(BG14*BB14,0) -> 0 | BJ14: =IFERROR(BG14*BC14,0) -> 98000 | BL14: =$AW14*BE14 -> 0 | BM14: =$AW14*BF14 -> 0 | BN14: =$AW14*BG14 -> 0 | BO14: =$AW14*BH14 -> 0 | BP14: =$AW14*BI14 -> 0 | BQ14: =$AW14*BJ14 -> 0
C15: 103 | D15: ZLI1-New Lease | E15: Jason Kirkham | F15: Jacob Sleight | G15: ZLI1_QC | H15: 2026 | I15: Project | J15: LOI Concluded | K15: Active | L15: R2L | M15: Quick Commerce | N15: New Lease | O15: Existing | P15: 2335 South Hanley Road Brentwood MO | R15: 2335 South Hanley Road | S15: Brentwood | T15: MO | U15: 63144 | V15: United States | W15: 38.61803 | X15: -90.33489 | Y15: 4700 | Z15: 0.34 | AA15: 45974 | AB15: 46066 | AC15: 46091 | AF15: 46199 | AI15: a0ERc00000SoniDMAR | AJ15: a00at00000JmA8fAAF | AL15: New | AR15: x | AZ15: x | BA15: =IFERROR(VLOOKUP($AX15,List!B:C,2,FALSE),"N/A") -> N/A | BB15: =IF(AX15="YES",0, IF(AX15="NO",(1-BA15),"N/A")) -> N/A | BC15: =IF(AX15="YES",(1-BA15),IF(AX15="NO",0,"N/A")) -> N/A | BE15: =IFERROR(AV15,0) -> 0 | BF15: =IFERROR(MAX(BE15-MIN(600000,BE15/2),0),0) -> 0 | BG15: =IFERROR(MIN(600000,BE15/2),0) -> 0 | BH15: =IFERROR(BG15*BA15,0) -> 0 | BI15: =IFERROR(BG15*BB15,0) -> 0 | BJ15: =IFERROR(BG15*BC15,0) -> 0 | BL15: =$AW15*BE15 -> 0 | BM15: =$AW15*BF15 -> 0 | BN15: =$AW15*BG15 -> 0 | BO15: =$AW15*BH15 -> 0 | BP15: =$AW15*BI15 -> 0 | BQ15: =$AW15*BJ15 -> 0
C16: 104 | D16: ZMP1-New Lease | E16: Jason Kirkham | F16: Jacob Sleight | G16: ZMP1 | H16: 2026 | I16: Project | J16: LOI Concluded | K16: Active | L16: R2L | M16: Quick Commerce | N16: New Lease | O16: Existing | P16: Golden Valley II 8337 10th Avenue North Golden Valley MN | R16: 8337 10th Avenue North | S16: Golden Valley | T16: MN | U16: 55427 | V16: United States | W16: 44.98866 | X16: -93.38609 | Y16: 6380 | Z16: 5.76 | AA16: 46045 | AB16: 46100 | AC16: 46051 | AF16: 46199 | AI16: a0ERc00000Trsg0MAB | AJ16: a00at00000PNuj6AAD | AL16: New | AR16: x | AZ16: x | BA16: =IFERROR(VLOOKUP($AX16,List!B:C,2,FALSE),"N/A") -> N/A | BB16: =IF(AX16="YES",0, IF(AX16="NO",(1-BA16),"N/A")) -> N/A | BC16: =IF(AX16="YES",(1-BA16),IF(AX16="NO",0,"N/A")) -> N/A | BE16: =IFERROR(AV16,0) -> 0 | BF16: =IFERROR(MAX(BE16-MIN(600000,BE16/2),0),0) -> 0 | BG16: =IFERROR(MIN(600000,BE16/2),0) -> 0 | BH16: =IFERROR(BG16*BA16,0) -> 0 | BI16: =IFERROR(BG16*BB16,0) -> 0 | BJ16: =IFERROR(BG16*BC16,0) -> 0 | BL16: =$AW16*BE16 -> 0 | BM16: =$AW16*BF16 -> 0 | BN16: =$AW16*BG16 -> 0 | BO16: =$AW16*BH16 -> 0 | BP16: =$AW16*BI16 -> 0 | BQ16: =$AW16*BJ16 -> 0
C17: 129 | D17: OPA8-New Lease | E17: Jason Kirkham | F17: Mackenzie Floyd | G17: OPA8 | H17: 2027 | I17: Project | J17: Client Approved | K17: Active | L17: CF | M17: 1-DC | N17: New Lease | O17: Spec | P17: Manchester Commerce Center Building 2 Manchester PA | Q17: I-78 / I-81 Corridor | R17: North Susquehanna Trail | S17: Manchester | T17: PA | U17: 17404 | V17: United States | W17: 40.047658 | X17: -76.75915 | Y17: 1127142 | Z17: 98.49 | AA17: 45637 | AB17: 46002 | AC17: 46002 | AD17: 46118 | AF17: 46203 | AI17: a0ERc00000Qrct2MAB | AJ17: a00at00000G9HIOAA3 | AL17: New | AR17: x | AZ17: x | BA17: =IFERROR(VLOOKUP($AX17,List!B:C,2,FALSE),"N/A") -> N/A | BB17: =IF(AX17="YES",0, IF(AX17="NO",(1-BA17),"N/A")) -> N/A | BC17: =IF(AX17="YES",(1-BA17),IF(AX17="NO",0,"N/A")) -> N/A | BE17: =IFERROR(AV17,0) -> 0 | BF17: =IFERROR(MAX(BE17-MIN(600000,BE17/2),0),0) -> 0 | BG17: =IFERROR(MIN(600000,BE17/2),0) -> 0 | BH17: =IFERROR(BG17*BA17,0) -> 0 | BI17: =IFERROR(BG17*BB17,0) -> 0 | BJ17: =IFERROR(BG17*BC17,0) -> 0 | BL17: =$AW17*BE17 -> 0 | BM17: =$AW17*BF17 -> 0 | BN17: =$AW17*BG17 -> 0 | BO17: =$AW17*BH17 -> 0 | BP17: =$AW17*BI17 -> 0 | BQ17: =$AW17*BJ17 -> 0
C18: 149 | D18: SOU3-New Lease | E18: Jason Kirkham | F18: Dominic Nicholas | G18: SOU3 | H18: 2027 | I18: Project | J18: LOI Concluded | K18: Active | L18: R2L | M18: Sub Same Day FC | N18: New Lease | O18: Spec | P18: 8001 Air Commerce Drive Louisville KY | Q18: Louisville | R18: 8001 Air Commerce Drive | S18: Louisville | T18: KY | U18: 40219 | V18: United States | W18: 38.133868 | X18: -85.715451 | Y18: 324576 | Z18: 23 | AA18: 45924 | AB18: 46008 | AC18: 46065 | AF18: 46208 | AI18: a0ERc00000Qvqm6MAB | AJ18: a00at00000HqH1NAAV | AL18: New | AR18: x | AZ18: x | BA18: =IFERROR(VLOOKUP($AX18,List!B:C,2,FALSE),"N/A") -> N/A | BB18: =IF(AX18="YES",0, IF(AX18="NO",(1-BA18),"N/A")) -> N/A | BC18: =IF(AX18="YES",(1-BA18),IF(AX18="NO",0,"N/A")) -> N/A | BE18: =IFERROR(AV18,0) -> 0 | BF18: =IFERROR(MAX(BE18-MIN(600000,BE18/2),0),0) -> 0 | BG18: =IFERROR(MIN(600000,BE18/2),0) -> 0 | BH18: =IFERROR(BG18*BA18,0) -> 0 | BI18: =IFERROR(BG18*BB18,0) -> 0 | BJ18: =IFERROR(BG18*BC18,0) -> 0 | BL18: =$AW18*BE18 -> 0 | BM18: =$AW18*BF18 -> 0 | BN18: =$AW18*BG18 -> 0 | BO18: =$AW18*BH18 -> 0 | BP18: =$AW18*BI18 -> 0 | BQ18: =$AW18*BJ18 -> 0
C19: 207 | D19: 27_RSR DS_NA_US_Middlesboro_DTS4-1 | E19: Jason Kirkham | F19: Lauren Bays | H19: 2027 | I19: Requirement | J19: New Project | K19: Active | L19: R2L | M19: RSR - DS | N19: New Lease | O19: Existing | S19: Middlesboro | T19: KY | V19: United States | AF19: 46238 | AH19: No | AI19: a2PRc000001ehiRMAQ | AJ19: a00at00000NWm2fAAD | AL19: New | AR19: x | AZ19: x | BA19: =IFERROR(VLOOKUP($AX19,List!B:C,2,FALSE),"N/A") -> N/A | BB19: =IF(AX19="YES",0, IF(AX19="NO",(1-BA19),"N/A")) -> N/A | BC19: =IF(AX19="YES",(1-BA19),IF(AX19="NO",0,"N/A")) -> N/A | BE19: =IFERROR(AV19,0) -> 0 | BF19: =IFERROR(MAX(BE19-MIN(600000,BE19/2),0),0) -> 0 | BG19: =IFERROR(MIN(600000,BE19/2),0) -> 0 | BH19: =IFERROR(BG19*BA19,0) -> 0 | BI19: =IFERROR(BG19*BB19,0) -> 0 | BJ19: =IFERROR(BG19*BC19,0) -> 0 | BL19: =$AW19*BE19 -> 0 | BM19: =$AW19*BF19 -> 0 | BN19: =$AW19*BG19 -> 0 | BO19: =$AW19*BH19 -> 0 | BP19: =$AW19*BI19 -> 0 | BQ19: =$AW19*BJ19 -> 0
C20: 224 | D20: 26_QC_NA_US_Minneapolis_Summit Hills | E20: Jason Kirkham | F20: Jacob Sleight | H20: 2026 | I20: Requirement | J20: Market Surveyed | K20: Active | L20: Quick Commerce | M20: Quick Commerce | N20: New Lease | O20: Existing | Q20: Minneapolis/St. Paul | S20: Minneapolis | T20: MN | V20: United States | AF20: 46245 | AH20: No | AI20: a2PRc000001n2GDMAY | AJ20: a00at00000POVKSAA5 | AL20: New | AR20: x | AZ20: x | BA20: =IFERROR(VLOOKUP($AX20,List!B:C,2,FALSE),"N/A") -> N/A | BB20: =IF(AX20="YES",0, IF(AX20="NO",(1-BA20),"N/A")) -> N/A | BC20: =IF(AX20="YES",(1-BA20),IF(AX20="NO",0,"N/A")) -> N/A | BE20: =IFERROR(AV20,0) -> 0 | BF20: =IFERROR(MAX(BE20-MIN(600000,BE20/2),0),0) -> 0 | BG20: =IFERROR(MIN(600000,BE20/2),0) -> 0 | BH20: =IFERROR(BG20*BA20,0) -> 0 | BI20: =IFERROR(BG20*BB20,0) -> 0 | BJ20: =IFERROR(BG20*BC20,0) -> 0 | BL20: =$AW20*BE20 -> 0 | BM20: =$AW20*BF20 -> 0 | BN20: =$AW20*BG20 -> 0 | BO20: =$AW20*BH20 -> 0 | BP20: =$AW20*BI20 -> 0 | BQ20: =$AW20*BJ20 -> 0
C21: 232 | D21: 26_QC_NA_US_St Louis_DT St Louis | E21: Jason Kirkham | F21: Jacob Sleight | H21: 2026 | I21: Requirement | J21: Market Surveyed | K21: Active | L21: Quick Commerce | M21: Quick Commerce | N21: New Lease | O21: Existing | Q21: St. Louis | S21: St Louis | T21: MO | V21: United States | AF21: 46252 | AH21: No | AI21: a2PRc000001rKrIMAU | AJ21: a00at00000U8E4XAAV | AL21: New | AR21: x | AZ21: x | BA21: =IFERROR(VLOOKUP($AX21,List!B:C,2,FALSE),"N/A") -> N/A | BB21: =IF(AX21="YES",0, IF(AX21="NO",(1-BA21),"N/A")) -> N/A | BC21: =IF(AX21="YES",(1-BA21),IF(AX21="NO",0,"N/A")) -> N/A | BE21: =IFERROR(AV21,0) -> 0 | BF21: =IFERROR(MAX(BE21-MIN(600000,BE21/2),0),0) -> 0 | BG21: =IFERROR(MIN(600000,BE21/2),0) -> 0 | BH21: =IFERROR(BG21*BA21,0) -> 0 | BI21: =IFERROR(BG21*BB21,0) -> 0 | BJ21: =IFERROR(BG21*BC21,0) -> 0 | BL21: =$AW21*BE21 -> 0 | BM21: =$AW21*BF21 -> 0 | BN21: =$AW21*BG21 -> 0 | BO21: =$AW21*BH21 -> 0 | BP21: =$AW21*BI21 -> 0 | BQ21: =$AW21*BJ21 -> 0
C22: 237 | D22: 26_QC_NA_US_Kansas City_DT Kansas City | E22: Jason Kirkham | F22: Jacob Sleight | H22: 2026 | I22: Requirement | J22: Market Surveyed | K22: Active | L22: Quick Commerce | M22: Quick Commerce | N22: New Lease | O22: Existing | Q22: Kansas City | S22: Kansas City | T22: MO | V22: United States | AF22: 46259 | AH22: No | AI22: a2PRc000001toI9MAI | AJ22: a00at00000QcfJRAAZ | AL22: New | AR22: x | AZ22: x | BA22: =IFERROR(VLOOKUP($AX22,List!B:C,2,FALSE),"N/A") -> N/A | BB22: =IF(AX22="YES",0, IF(AX22="NO",(1-BA22),"N/A")) -> N/A | BC22: =IF(AX22="YES",(1-BA22),IF(AX22="NO",0,"N/A")) -> N/A | BE22: =IFERROR(AV22,0) -> 0 | BF22: =IFERROR(MAX(BE22-MIN(600000,BE22/2),0),0) -> 0 | BG22: =IFERROR(MIN(600000,BE22/2),0) -> 0 | BH22: =IFERROR(BG22*BA22,0) -> 0 | BI22: =IFERROR(BG22*BB22,0) -> 0 | BJ22: =IFERROR(BG22*BC22,0) -> 0 | BL22: =$AW22*BE22 -> 0 | BM22: =$AW22*BF22 -> 0 | BN22: =$AW22*BG22 -> 0 | BO22: =$AW22*BH22 -> 0 | BP22: =$AW22*BI22 -> 0 | BQ22: =$AW22*BJ22 -> 0
C23: 256 | D23: 26_QC_NA_US_Minneapolis_Uptown Minneapolis | E23: Jason Kirkham | F23: Jacob Sleight | H23: 2028 | I23: Requirement | J23: New Project | K23: Active | L23: Quick Commerce | M23: Quick Commerce | N23: New Lease | O23: Existing | Q23: Minneapolis/St. Paul | S23: Minneapolis | T23: MN | V23: United States | AF23: 46268 | AH23: No | AI23: a2PRc000001toIBMAY | AJ23: a00at00000VJPc1AAH | AL23: New | AR23: x | AZ23: x | BA23: =IFERROR(VLOOKUP($AX23,List!B:C,2,FALSE),"N/A") -> N/A | BB23: =IF(AX23="YES",0, IF(AX23="NO",(1-BA23),"N/A")) -> N/A | BC23: =IF(AX23="YES",(1-BA23),IF(AX23="NO",0,"N/A")) -> N/A | BE23: =IFERROR(AV23,0) -> 0 | BF23: =IFERROR(MAX(BE23-MIN(600000,BE23/2),0),0) -> 0 | BG23: =IFERROR(MIN(600000,BE23/2),0) -> 0 | BH23: =IFERROR(BG23*BA23,0) -> 0 | BI23: =IFERROR(BG23*BB23,0) -> 0 | BJ23: =IFERROR(BG23*BC23,0) -> 0 | BL23: =$AW23*BE23 -> 0 | BM23: =$AW23*BF23 -> 0 | BN23: =$AW23*BG23 -> 0 | BO23: =$AW23*BH23 -> 0 | BP23: =$AW23*BI23 -> 0 | BQ23: =$AW23*BJ23 -> 0
C24: 273 | D24: ACY4-Purchase | E24: Jason Kirkham | F24: Mackenzie Floyd | G24: ACY4 | H24: 2029 | I24: Project | J24: PSA Execution | K24: Active | L24: CF | M24: AR Sortable | N24: Purchase | O24: Build to Suit | P24: Atlantic City Racecourse 4501 East Black Horse Pike Mays Landing NJ | Q24: Northern New Jersey | R24: 4501 East Black Horse Pike | S24: Mays Landing | T24: NJ | U24: 8330 | V24: United States | W24: 39.461941 | X24: -74.640991 | Z24: 255.95 | AB24: 45767 | AC24: 45296 | AD24: 46156 | AE24: 45411 | AG24: 46280 | AI24: a0ERc000009LLU7MAO | AJ24: a003t00001JUQN7AAP | AL24: Existing | AR24: x | AS24: 45411 | AT24: 46509 | AU24: 400000 | AV24: 400000 | AW24: 0.75 | AX24: NO | AZ24: x | BA24: =IFERROR(VLOOKUP($AX24,List!B:C,2,FALSE),"N/A") -> 0.2 | BB24: =IF(AX24="YES",0, IF(AX24="NO",(1-BA24),"N/A")) -> 0.8 | BC24: =IF(AX24="YES",(1-BA24),IF(AX24="NO",0,"N/A")) -> 0 | BE24: =IFERROR(AV24,0) -> 400000 | BF24: =IFERROR(MAX(BE24-MIN(600000,BE24/2),0),0) -> 200000 | BG24: =IFERROR(MIN(600000,BE24/2),0) -> 200000 | BH24: =IFERROR(BG24*BA24,0) -> 40000 | BI24: =IFERROR(BG24*BB24,0) -> 160000 | BJ24: =IFERROR(BG24*BC24,0) -> 0 | BL24: =$AW24*BE24 -> 300000 | BM24: =$AW24*BF24 -> 150000 | BN24: =$AW24*BG24 -> 150000 | BO24: =$AW24*BH24 -> 30000 | BP24: =$AW24*BI24 -> 120000 | BQ24: =$AW24*BJ24 -> 0
C25: 304 | D25: DFR5 (FKA WKM2)-Purchase | E25: Jason Kirkham | F25: Mackenzie Floyd | G25: DFR5 | H25: 2027 | I25: Project | J25: PSA Execution | K25: Active | L25: R2L | M25: RSR - DS | N25: Purchase | O25: Build to Suit | P25: Richmond County Commerce Park History Land Highway Warsaw VA | R25: History Land Highway | S25: Warsaw | T25: VA | U25: 22572 | V25: United States | W25: 37.965571 | X25: -76.752115 | Y25: 110000 | Z25: 0 | AA25: 45660 | AB25: 46010 | AC25: 46023 | AE25: 46135 | AG25: 46297 | AI25: a0ERc00000R1hD6MAJ | AJ25: a003t00001JVpmhAAD | AL25: Existing | AR25: x | AS25: 45700 | AT25: 46249 | AU25: 400000 | AV25: 460000 | AW25: 0.25 | AX25: YES | AZ25: x | BA25: =IFERROR(VLOOKUP($AX25,List!B:C,2,FALSE),"N/A") -> 0.6 | BB25: =IF(AX25="YES",0, IF(AX25="NO",(1-BA25),"N/A")) -> 0 | BC25: =IF(AX25="YES",(1-BA25),IF(AX25="NO",0,"N/A")) -> 0.4 | BE25: =IFERROR(AV25,0) -> 460000 | BF25: =IFERROR(MAX(BE25-MIN(600000,BE25/2),0),0) -> 230000 | BG25: =IFERROR(MIN(600000,BE25/2),0) -> 230000 | BH25: =IFERROR(BG25*BA25,0) -> 138000 | BI25: =IFERROR(BG25*BB25,0) -> 0 | BJ25: =IFERROR(BG25*BC25,0) -> 92000 | BL25: =$AW25*BE25 -> 115000 | BM25: =$AW25*BF25 -> 57500 | BN25: =$AW25*BG25 -> 57500 | BO25: =$AW25*BH25 -> 34500 | BP25: =$AW25*BI25 -> 0 | BQ25: =$AW25*BJ25 -> 23000
C26: 321 | D26: CMH8-Purchase | E26: Jason Kirkham | F26: Mackenzie Floyd | G26: CMH8 | H26: 2028 | I26: Project | J26: LOI/Offers | K26: Active | L26: CF | M26: Other | N26: Purchase | O26: Build to Suit | P26: C5 Gateway Logistics Center Bldg 1 West Jefferson OH | Q26: Columbus | R26: 1025 Enterprise Parkway South | S26: West Jefferson | T26: OH | U26: 43162 | V26: United States | W26: 39.939331 | X26: -83.317411 | Y26: 933656 | Z26: 108.55 | AB26: 45770 | AC26: 45775 | AG26: 46325 | AI26: a0ERc00000I1YF7MAN | AJ26: a00at000003mYFQAA2 | AL26: Existing | AR26: x | AS26: 45900 | AT26: 46882 | AU26: 400000 | AV26: 490000 | AW26: 0 | AX26: NO | AZ26: x | BA26: =IFERROR(VLOOKUP($AX26,List!B:C,2,FALSE),"N/A") -> 0.2 | BB26: =IF(AX26="YES",0, IF(AX26="NO",(1-BA26),"N/A")) -> 0.8 | BC26: =IF(AX26="YES",(1-BA26),IF(AX26="NO",0,"N/A")) -> 0 | BE26: =IFERROR(AV26,0) -> 490000 | BF26: =IFERROR(MAX(BE26-MIN(600000,BE26/2),0),0) -> 245000 | BG26: =IFERROR(MIN(600000,BE26/2),0) -> 245000 | BH26: =IFERROR(BG26*BA26,0) -> 49000 | BI26: =IFERROR(BG26*BB26,0) -> 196000 | BJ26: =IFERROR(BG26*BC26,0) -> 0 | BL26: =$AW26*BE26 -> 0 | BM26: =$AW26*BF26 -> 0 | BN26: =$AW26*BG26 -> 0 | BO26: =$AW26*BH26 -> 0 | BP26: =$AW26*BI26 -> 0 | BQ26: =$AW26*BJ26 -> 0
C27: 347 | D27: 28_Flex_Shell_NA_US_MidWest_28_Flex_Shell_9 | E27: Jason Kirkham | F27: Mackenzie Floyd | H27: 2028 | I27: Requirement | J27: Market Surveyed | K27: Active | L27: CF | M27: Other | N27: Purchase | O27: Build to Suit | S27: TBD | V27: United States | AG27: 46365 | AH27: No | AI27: a2PRc000001Sdp9MAC | AJ27: a00at00000GBpVxAAL | AL27: New | AR27: x | AZ27: x | BA27: =IFERROR(VLOOKUP($AX27,List!B:C,2,FALSE),"N/A") -> N/A | BB27: =IF(AX27="YES",0, IF(AX27="NO",(1-BA27),"N/A")) -> N/A | BC27: =IF(AX27="YES",(1-BA27),IF(AX27="NO",0,"N/A")) -> N/A | BE27: =IFERROR(AV27,0) -> 0 | BF27: =IFERROR(MAX(BE27-MIN(600000,BE27/2),0),0) -> 0 | BG27: =IFERROR(MIN(600000,BE27/2),0) -> 0 | BH27: =IFERROR(BG27*BA27,0) -> 0 | BI27: =IFERROR(BG27*BB27,0) -> 0 | BJ27: =IFERROR(BG27*BC27,0) -> 0 | BL27: =$AW27*BE27 -> 0 | BM27: =$AW27*BF27 -> 0 | BN27: =$AW27*BG27 -> 0 | BO27: =$AW27*BH27 -> 0 | BP27: =$AW27*BI27 -> 0 | BQ27: =$AW27*BJ27 -> 0
C28: 350 | D28: 28_SSD FC_NA_US_Cleveland_SOHC | E28: Jason Kirkham | F28: Dominic Nicholas | H28: 2028 | I28: Requirement | J28: Market Surveyed | K28: Active | L28: R2L | M28: Sub Same Day FC | N28: New Lease | O28: Existing | Q28: Cleveland | S28: Cleveland | T28: OH | U28: 44124 | V28: United States | AF28: 46368 | AH28: No | AI28: a2PRc000001V0jCMAS | AJ28: a00at00000Hqha9AAB | AL28: New | AR28: x | AZ28: x | BA28: =IFERROR(VLOOKUP($AX28,List!B:C,2,FALSE),"N/A") -> N/A | BB28: =IF(AX28="YES",0, IF(AX28="NO",(1-BA28),"N/A")) -> N/A | BC28: =IF(AX28="YES",(1-BA28),IF(AX28="NO",0,"N/A")) -> N/A | BE28: =IFERROR(AV28,0) -> 0 | BF28: =IFERROR(MAX(BE28-MIN(600000,BE28/2),0),0) -> 0 | BG28: =IFERROR(MIN(600000,BE28/2),0) -> 0 | BH28: =IFERROR(BG28*BA28,0) -> 0 | BI28: =IFERROR(BG28*BB28,0) -> 0 | BJ28: =IFERROR(BG28*BC28,0) -> 0 | BL28: =$AW28*BE28 -> 0 | BM28: =$AW28*BF28 -> 0 | BN28: =$AW28*BG28 -> 0 | BO28: =$AW28*BH28 -> 0 | BP28: =$AW28*BI28 -> 0 | BQ28: =$AW28*BJ28 -> 0
C29: 383 | D29: 28_Flex_Shell_NA_US_GreatLakes_28_Flex_Shell_1 | E29: Jason Kirkham | F29: Nicole Rasmussen | H29: 2028 | I29: Requirement | J29: Market Surveyed | K29: Active | L29: CF | M29: Flex Shell | N29: Purchase | O29: Build to Suit | S29: Mid-Missouri | V29: United States | AG29: 46386 | AH29: No | AI29: a2PRc000001SdnUMAS | AJ29: a00at00000GBfcvAAD | AL29: New | AR29: x | AZ29: x | BA29: =IFERROR(VLOOKUP($AX29,List!B:C,2,FALSE),"N/A") -> N/A | BB29: =IF(AX29="YES",0, IF(AX29="NO",(1-BA29),"N/A")) -> N/A | BC29: =IF(AX29="YES",(1-BA29),IF(AX29="NO",0,"N/A")) -> N/A | BE29: =IFERROR(AV29,0) -> 0 | BF29: =IFERROR(MAX(BE29-MIN(600000,BE29/2),0),0) -> 0 | BG29: =IFERROR(MIN(600000,BE29/2),0) -> 0 | BH29: =IFERROR(BG29*BA29,0) -> 0 | BI29: =IFERROR(BG29*BB29,0) -> 0 | BJ29: =IFERROR(BG29*BC29,0) -> 0 | BL29: =$AW29*BE29 -> 0 | BM29: =$AW29*BF29 -> 0 | BN29: =$AW29*BG29 -> 0 | BO29: =$AW29*BH29 -> 0 | BP29: =$AW29*BI29 -> 0 | BQ29: =$AW29*BJ29 -> 0
C30: 389 | D30: DOH3-1-Purchase | E30: Jason Kirkham | F30: Lauren Bays | G30: DOH3-1 | H30: 2028 | I30: Project | J30: Site Selected | K30: Active | L30: AMZL | M30: Delivery Station | N30: Purchase | O30: Build to Suit | P30: Heritage Business Park I-75 & SR73 Franklin OH | Q30: Cincinnati | R30: I-75 & SR73 | S30: Franklin | T30: OH | U30: 45005 | V30: United States | W30: 39.570953 | X30: -84.273419 | Y30: 216018 | Z30: 140 | AA30: 45876 | AB30: 46063 | AG30: 46408 | AI30: a0ERc00000SdoXuMAJ | AJ30: a00at00000F0pmfAAB | AL30: Existing | AR30: x | AZ30: x | BA30: =IFERROR(VLOOKUP($AX30,List!B:C,2,FALSE),"N/A") -> N/A | BB30: =IF(AX30="YES",0, IF(AX30="NO",(1-BA30),"N/A")) -> N/A | BC30: =IF(AX30="YES",(1-BA30),IF(AX30="NO",0,"N/A")) -> N/A | BE30: =IFERROR(AV30,0) -> 0 | BF30: =IFERROR(MAX(BE30-MIN(600000,BE30/2),0),0) -> 0 | BG30: =IFERROR(MIN(600000,BE30/2),0) -> 0 | BH30: =IFERROR(BG30*BA30,0) -> 0 | BI30: =IFERROR(BG30*BB30,0) -> 0 | BJ30: =IFERROR(BG30*BC30,0) -> 0 | BL30: =$AW30*BE30 -> 0 | BM30: =$AW30*BF30 -> 0 | BN30: =$AW30*BG30 -> 0 | BO30: =$AW30*BH30 -> 0 | BP30: =$AW30*BI30 -> 0 | BQ30: =$AW30*BJ30 -> 0
C31: 390 | D31: DOH2-1-Purchase | E31: Jason Kirkham | F31: Lauren Bays | G31: DOH2-1 | H31: 2028 | I31: Project | J31: Site Selected | K31: Active | L31: AMZL | M31: Delivery Station | N31: Purchase | O31: Build to Suit | P31: 4400 Half-Acre Road Batavia OH | Q31: Cincinnati | R31: 4400 Half-Acre Road | S31: Batavia | T31: OH | U31: 45103 | V31: United States | W31: 39.072139 | X31: -84.086683 | Z31: 160 | AB31: 46113 | AG31: 46408 | AI31: a0ERc00000UKmwrMAD | AJ31: a00at00000F0fdiAAB | AL31: Existing | AR31: x | AZ31: x | BA31: =IFERROR(VLOOKUP($AX31,List!B:C,2,FALSE),"N/A") -> N/A | BB31: =IF(AX31="YES",0, IF(AX31="NO",(1-BA31),"N/A")) -> N/A | BC31: =IF(AX31="YES",(1-BA31),IF(AX31="NO",0,"N/A")) -> N/A | BE31: =IFERROR(AV31,0) -> 0 | BF31: =IFERROR(MAX(BE31-MIN(600000,BE31/2),0),0) -> 0 | BG31: =IFERROR(MIN(600000,BE31/2),0) -> 0 | BH31: =IFERROR(BG31*BA31,0) -> 0 | BI31: =IFERROR(BG31*BB31,0) -> 0 | BJ31: =IFERROR(BG31*BC31,0) -> 0 | BL31: =$AW31*BE31 -> 0 | BM31: =$AW31*BF31 -> 0 | BN31: =$AW31*BG31 -> 0 | BO31: =$AW31*BH31 -> 0 | BP31: =$AW31*BI31 -> 0 | BQ31: =$AW31*BJ31 -> 0
C32: 410 | D32: 28_RSR DS_NA_US_Charleston_DVW3-1 | E32: Jason Kirkham | F32: Kinsley West | H32: 2028 | I32: Requirement | J32: New Project | K32: Active | L32: R2L | M32: RSR - DS | N32: Purchase | O32: Build to Suit | Q32: Charleston (WV) | S32: Charleston | T32: WV | V32: United States | AG32: 46444 | AH32: No | AI32: a2PRc000001WSQRMA4 | AJ32: a00at00000IOzxeAAD | AL32: New | AR32: x | AZ32: x | BA32: =IFERROR(VLOOKUP($AX32,List!B:C,2,FALSE),"N/A") -> N/A | BB32: =IF(AX32="YES",0, IF(AX32="NO",(1-BA32),"N/A")) -> N/A | BC32: =IF(AX32="YES",(1-BA32),IF(AX32="NO",0,"N/A")) -> N/A | BE32: =IFERROR(AV32,0) -> 0 | BF32: =IFERROR(MAX(BE32-MIN(600000,BE32/2),0),0) -> 0 | BG32: =IFERROR(MIN(600000,BE32/2),0) -> 0 | BH32: =IFERROR(BG32*BA32,0) -> 0 | BI32: =IFERROR(BG32*BB32,0) -> 0 | BJ32: =IFERROR(BG32*BC32,0) -> 0 | BL32: =$AW32*BE32 -> 0 | BM32: =$AW32*BF32 -> 0 | BN32: =$AW32*BG32 -> 0 | BO32: =$AW32*BH32 -> 0 | BP32: =$AW32*BI32 -> 0 | BQ32: =$AW32*BJ32 -> 0
C33: 420 | D33: 28_RSR DS_NA_US_Seaford_DDL7-1 | E33: Jason Kirkham | F33: Mackenzie Floyd | H33: 2028 | I33: Requirement | J33: Market Surveyed | K33: Active | L33: R2L | M33: RSR - DS | N33: Purchase | O33: Build to Suit | Q33: Salisbury | S33: Seaford | T33: DE | V33: United States | AG33: 46451 | AH33: No | AI33: a2PRc000001WSSAMA4 | AJ33: a00at00000IOjjGAAT | AL33: New | AR33: x | AZ33: x | BA33: =IFERROR(VLOOKUP($AX33,List!B:C,2,FALSE),"N/A") -> N/A | BB33: =IF(AX33="YES",0, IF(AX33="NO",(1-BA33),"N/A")) -> N/A | BC33: =IF(AX33="YES",(1-BA33),IF(AX33="NO",0,"N/A")) -> N/A | BE33: =IFERROR(AV33,0) -> 0 | BF33: =IFERROR(MAX(BE33-MIN(600000,BE33/2),0),0) -> 0 | BG33: =IFERROR(MIN(600000,BE33/2),0) -> 0 | BH33: =IFERROR(BG33*BA33,0) -> 0 | BI33: =IFERROR(BG33*BB33,0) -> 0 | BJ33: =IFERROR(BG33*BC33,0) -> 0 | BL33: =$AW33*BE33 -> 0 | BM33: =$AW33*BF33 -> 0 | BN33: =$AW33*BG33 -> 0 | BO33: =$AW33*BH33 -> 0 | BP33: =$AW33*BI33 -> 0 | BQ33: =$AW33*BJ33 -> 0
C34: 434 | D34: 28_AMZL_NA_US_Lexington_DLE5-1 | E34: Jason Kirkham | F34: Lauren Bays | H34: 2028 | I34: Requirement | J34: Market Surveyed | K34: Active | L34: AMZL | M34: Delivery Station | N34: Purchase | O34: Build to Suit | S34: Lexington | T34: KY | V34: United States | AG34: 46482 | AH34: No | AI34: a2PRc000001ld3rMAA | AJ34: a00at00000SJfDyAAL | AL34: New | AR34: x | AZ34: x | BA34: =IFERROR(VLOOKUP($AX34,List!B:C,2,FALSE),"N/A") -> N/A | BB34: =IF(AX34="YES",0, IF(AX34="NO",(1-BA34),"N/A")) -> N/A | BC34: =IF(AX34="YES",(1-BA34),IF(AX34="NO",0,"N/A")) -> N/A | BE34: =IFERROR(AV34,0) -> 0 | BF34: =IFERROR(MAX(BE34-MIN(600000,BE34/2),0),0) -> 0 | BG34: =IFERROR(MIN(600000,BE34/2),0) -> 0 | BH34: =IFERROR(BG34*BA34,0) -> 0 | BI34: =IFERROR(BG34*BB34,0) -> 0 | BJ34: =IFERROR(BG34*BC34,0) -> 0 | BL34: =$AW34*BE34 -> 0 | BM34: =$AW34*BF34 -> 0 | BN34: =$AW34*BG34 -> 0 | BO34: =$AW34*BH34 -> 0 | BP34: =$AW34*BI34 -> 0 | BQ34: =$AW34*BJ34 -> 0
C35: 435 | D35: 28_AMZL_NA_US_Louisville_DLK4-1 | E35: Jason Kirkham | F35: Lauren Bays | H35: 2028 | I35: Requirement | J35: New Project | K35: Active | L35: AMZL | M35: Delivery Station | N35: Purchase | O35: Build to Suit | Q35: Louisville | S35: Louisville | T35: KY | V35: United States | AG35: 46482 | AH35: No | AI35: a2PRc000001ld3sMAA | AJ35: a00at00000SK1WFAA1 | AL35: New | AR35: x | AZ35: x | BA35: =IFERROR(VLOOKUP($AX35,List!B:C,2,FALSE),"N/A") -> N/A | BB35: =IF(AX35="YES",0, IF(AX35="NO",(1-BA35),"N/A")) -> N/A | BC35: =IF(AX35="YES",(1-BA35),IF(AX35="NO",0,"N/A")) -> N/A | BE35: =IFERROR(AV35,0) -> 0 | BF35: =IFERROR(MAX(BE35-MIN(600000,BE35/2),0),0) -> 0 | BG35: =IFERROR(MIN(600000,BE35/2),0) -> 0 | BH35: =IFERROR(BG35*BA35,0) -> 0 | BI35: =IFERROR(BG35*BB35,0) -> 0 | BJ35: =IFERROR(BG35*BC35,0) -> 0 | BL35: =$AW35*BE35 -> 0 | BM35: =$AW35*BF35 -> 0 | BN35: =$AW35*BG35 -> 0 | BO35: =$AW35*BH35 -> 0 | BP35: =$AW35*BI35 -> 0 | BQ35: =$AW35*BJ35 -> 0
C36: 437 | D36: HIA2-Purchase | E36: Jason Kirkham | F36: Mackenzie Floyd | G36: HIA2 | H36: 2029 | I36: Project | J36: PSA Execution | K36: Active | L36: CF | M36: Other | N36: Purchase | O36: Build to Suit | P36: 3055 Black Gap Road Chambersburg PA | Q36: I-78 / I-81 Corridor | R36: 3055 Black Gap Road | S36: Chambersburg | T36: PA | U36: 17202 | V36: United States | W36: 39.954904 | X36: -77.575017 | Z36: 130 | AB36: 46091 | AC36: 45958 | AE36: 46106 | AG36: 46484 | AI36: a0ERc00000TcpVVMAZ | AJ36: a00at00000LvxtmAAB | AL36: New | AR36: x | AZ36: x | BA36: =IFERROR(VLOOKUP($AX36,List!B:C,2,FALSE),"N/A") -> N/A | BB36: =IF(AX36="YES",0, IF(AX36="NO",(1-BA36),"N/A")) -> N/A | BC36: =IF(AX36="YES",(1-BA36),IF(AX36="NO",0,"N/A")) -> N/A | BE36: =IFERROR(AV36,0) -> 0 | BF36: =IFERROR(MAX(BE36-MIN(600000,BE36/2),0),0) -> 0 | BG36: =IFERROR(MIN(600000,BE36/2),0) -> 0 | BH36: =IFERROR(BG36*BA36,0) -> 0 | BI36: =IFERROR(BG36*BB36,0) -> 0 | BJ36: =IFERROR(BG36*BC36,0) -> 0 | BL36: =$AW36*BE36 -> 0 | BM36: =$AW36*BF36 -> 0 | BN36: =$AW36*BG36 -> 0 | BO36: =$AW36*BH36 -> 0 | BP36: =$AW36*BI36 -> 0 | BQ36: =$AW36*BJ36 -> 0
C37: 438 | D37: 29_Oth_NA_US_Shippensburg_Mid-Atlantic_Pipeline_3 | E37: Jason Kirkham | F37: Mackenzie Floyd | H37: 2029 | I37: Requirement | J37: On-Hold | K37: On-Hold | L37: CF | M37: Other | N37: Purchase | O37: Build to Suit | S37: Shippensburg | T37: PA | U37: 17257 | V37: United States | AG37: 46489 | AH37: Yes | AI37: a2PRc000001hOxpMAE | AJ37: a00at00000QII7gAAH | AL37: New | AR37: x | AZ37: x | BA37: =IFERROR(VLOOKUP($AX37,List!B:C,2,FALSE),"N/A") -> N/A | BB37: =IF(AX37="YES",0, IF(AX37="NO",(1-BA37),"N/A")) -> N/A | BC37: =IF(AX37="YES",(1-BA37),IF(AX37="NO",0,"N/A")) -> N/A | BE37: =IFERROR(AV37,0) -> 0 | BF37: =IFERROR(MAX(BE37-MIN(600000,BE37/2),0),0) -> 0 | BG37: =IFERROR(MIN(600000,BE37/2),0) -> 0 | BH37: =IFERROR(BG37*BA37,0) -> 0 | BI37: =IFERROR(BG37*BB37,0) -> 0 | BJ37: =IFERROR(BG37*BC37,0) -> 0 | BL37: =$AW37*BE37 -> 0 | BM37: =$AW37*BF37 -> 0 | BN37: =$AW37*BG37 -> 0 | BO37: =$AW37*BH37 -> 0 | BP37: =$AW37*BI37 -> 0 | BQ37: =$AW37*BJ37 -> 0
C38: 451 | D38: 28_RSR DS_NA_US_Ashland_DOH5-1 | E38: Jason Kirkham | F38: Lauren Bays | H38: 2028 | I38: Requirement | J38: New Project | K38: Active | L38: R2L | M38: RSR - DS | N38: Purchase | O38: Build to Suit | Q38: Cleveland | S38: Ashland | T38: OH | V38: United States | AG38: 46500 | AH38: No | AI38: a2PRc000001ld5WMAQ | AJ38: a00at00000SN4AtAAL | AL38: New | AR38: x | AZ38: x | BA38: =IFERROR(VLOOKUP($AX38,List!B:C,2,FALSE),"N/A") -> N/A | BB38: =IF(AX38="YES",0, IF(AX38="NO",(1-BA38),"N/A")) -> N/A | BC38: =IF(AX38="YES",(1-BA38),IF(AX38="NO",0,"N/A")) -> N/A | BE38: =IFERROR(AV38,0) -> 0 | BF38: =IFERROR(MAX(BE38-MIN(600000,BE38/2),0),0) -> 0 | BG38: =IFERROR(MIN(600000,BE38/2),0) -> 0 | BH38: =IFERROR(BG38*BA38,0) -> 0 | BI38: =IFERROR(BG38*BB38,0) -> 0 | BJ38: =IFERROR(BG38*BC38,0) -> 0 | BL38: =$AW38*BE38 -> 0 | BM38: =$AW38*BF38 -> 0 | BN38: =$AW38*BG38 -> 0 | BO38: =$AW38*BH38 -> 0 | BP38: =$AW38*BI38 -> 0 | BQ38: =$AW38*BJ38 -> 0
C39: 452 | D39: 28_RSR DS_NA_US_Findlay_DFI3-1 | E39: Jason Kirkham | F39: Lauren Bays | H39: 2028 | I39: Requirement | J39: New Project | K39: Active | L39: R2L | M39: RSR - DS | N39: Purchase | O39: Build to Suit | Q39: Toledo | S39: Findlay | T39: OH | V39: United States | AG39: 46500 | AH39: No | AI39: a2PRc000001ld73MAA | AJ39: a00at00000SNAmXAAX | AL39: New | AR39: x | AZ39: x | BA39: =IFERROR(VLOOKUP($AX39,List!B:C,2,FALSE),"N/A") -> N/A | BB39: =IF(AX39="YES",0, IF(AX39="NO",(1-BA39),"N/A")) -> N/A | BC39: =IF(AX39="YES",(1-BA39),IF(AX39="NO",0,"N/A")) -> N/A | BE39: =IFERROR(AV39,0) -> 0 | BF39: =IFERROR(MAX(BE39-MIN(600000,BE39/2),0),0) -> 0 | BG39: =IFERROR(MIN(600000,BE39/2),0) -> 0 | BH39: =IFERROR(BG39*BA39,0) -> 0 | BI39: =IFERROR(BG39*BB39,0) -> 0 | BJ39: =IFERROR(BG39*BC39,0) -> 0 | BL39: =$AW39*BE39 -> 0 | BM39: =$AW39*BF39 -> 0 | BN39: =$AW39*BG39 -> 0 | BO39: =$AW39*BH39 -> 0 | BP39: =$AW39*BI39 -> 0 | BQ39: =$AW39*BJ39 -> 0
C40: 453 | D40: 28_RSR DS_NA_US_London_DOL2-1 | E40: Jason Kirkham | F40: Lauren Bays | H40: 2028 | I40: Requirement | J40: New Project | K40: Active | L40: R2L | M40: RSR - DS | N40: Purchase | O40: Build to Suit | Q40: Louisville | S40: London | T40: KY | V40: United States | AG40: 46500 | AH40: No | AI40: a2PRc000001ld8bMAA | AJ40: a00at00000SK8UOAA1 | AL40: New | AR40: x | AZ40: x | BA40: =IFERROR(VLOOKUP($AX40,List!B:C,2,FALSE),"N/A") -> N/A | BB40: =IF(AX40="YES",0, IF(AX40="NO",(1-BA40),"N/A")) -> N/A | BC40: =IF(AX40="YES",(1-BA40),IF(AX40="NO",0,"N/A")) -> N/A | BE40: =IFERROR(AV40,0) -> 0 | BF40: =IFERROR(MAX(BE40-MIN(600000,BE40/2),0),0) -> 0 | BG40: =IFERROR(MIN(600000,BE40/2),0) -> 0 | BH40: =IFERROR(BG40*BA40,0) -> 0 | BI40: =IFERROR(BG40*BB40,0) -> 0 | BJ40: =IFERROR(BG40*BC40,0) -> 0 | BL40: =$AW40*BE40 -> 0 | BM40: =$AW40*BF40 -> 0 | BN40: =$AW40*BG40 -> 0 | BO40: =$AW40*BH40 -> 0 | BP40: =$AW40*BI40 -> 0 | BQ40: =$AW40*BJ40 -> 0
C41: 494 | D41: 29_ARS_631-Purchase | E41: Jason Kirkham | F41: Alexandra Seifert | G41: 29_ARS_631 | H41: 2029 | I41: Project | J41: LOI/Offers | K41: Active | L41: CF | M41: AR Sortable | N41: Purchase | O41: Build to Suit | P41: Lot G and H Gateway Commerce Center Drive East Edwardsville IL | Q41: St. Louis | R41: Gateway Commerce Center Drive East | S41: Edwardsville | T41: IL | U41: 62025 | V41: United States | W41: 38.763775 | X41: -90.038705 | Z41: 115.1 | AC41: 46146 | AG41: 46558 | AI41: a0ERc00000VWnqEMAT | AJ41: a00at000008K3eoAAC | AL41: New | AR41: x | AZ41: x | BA41: =IFERROR(VLOOKUP($AX41,List!B:C,2,FALSE),"N/A") -> N/A | BB41: =IF(AX41="YES",0, IF(AX41="NO",(1-BA41),"N/A")) -> N/A | BC41: =IF(AX41="YES",(1-BA41),IF(AX41="NO",0,"N/A")) -> N/A | BE41: =IFERROR(AV41,0) -> 0 | BF41: =IFERROR(MAX(BE41-MIN(600000,BE41/2),0),0) -> 0 | BG41: =IFERROR(MIN(600000,BE41/2),0) -> 0 | BH41: =IFERROR(BG41*BA41,0) -> 0 | BI41: =IFERROR(BG41*BB41,0) -> 0 | BJ41: =IFERROR(BG41*BC41,0) -> 0 | BL41: =$AW41*BE41 -> 0 | BM41: =$AW41*BF41 -> 0 | BN41: =$AW41*BG41 -> 0 | BO41: =$AW41*BH41 -> 0 | BP41: =$AW41*BI41 -> 0 | BQ41: =$AW41*BJ41 -> 0
C42: 515 | D42: TOL2-Purchase | E42: Jason Kirkham | F42: Mackenzie Floyd | G42: TOL2 | H42: 2029 | I42: Project | J42: LOI/Offers | K42: Active | L42: RELO | M42: RELO | N42: Purchase | O42: Build to Suit | P42: Deshler Road North Baltimore OH | Q42: Toledo | R42: Deshler Road | S42: North Baltimore | T42: OH | U42: 45872 | V42: United States | W42: 41.178019 | X42: -83.716702 | Y42: 1200000 | Z42: 131.59 | AA42: 46048 | AB42: 46149 | AC42: 46098 | AG42: 46813 | AI42: a0ERc00000Vl8I4MAJ | AJ42: a00at00000IvaagAAB | AL42: New | AR42: x | AZ42: x | BA42: =IFERROR(VLOOKUP($AX42,List!B:C,2,FALSE),"N/A") -> N/A | BB42: =IF(AX42="YES",0, IF(AX42="NO",(1-BA42),"N/A")) -> N/A | BC42: =IF(AX42="YES",(1-BA42),IF(AX42="NO",0,"N/A")) -> N/A | BE42: =IFERROR(AV42,0) -> 0 | BF42: =IFERROR(MAX(BE42-MIN(600000,BE42/2),0),0) -> 0 | BG42: =IFERROR(MIN(600000,BE42/2),0) -> 0 | BH42: =IFERROR(BG42*BA42,0) -> 0 | BI42: =IFERROR(BG42*BB42,0) -> 0 | BJ42: =IFERROR(BG42*BC42,0) -> 0 | BL42: =$AW42*BE42 -> 0 | BM42: =$AW42*BF42 -> 0 | BN42: =$AW42*BG42 -> 0 | BO42: =$AW42*BH42 -> 0 | BP42: =$AW42*BI42 -> 0 | BQ42: =$AW42*BJ42 -> 0
...

Sheet List
B2: Is there an Outside Broker | C2: KBC Advisor's Split | D2: Notes | F2: Closing Probability
B3: YES | C3: 0.6 | D3: Outside Broker | F3: 0
B4: NO | C4: 0.2 | D4: No Outside Broker | F4: 0.25
F5: 0.35
F6: 0.5
F7: 0.6
F8: 0.75
F9: 0.9
F10: 1
